<?xml version="1.0" encoding="UTF-8"?>
<testng-results ignored="1" total="3" passed="0" failed="1" skipped="1">
  <reporter-output>
    <line>
      <![CDATA[User Modified Successfully]]>
    </line>
  </reporter-output>
  <suite started-at="2021-04-10T02:28:53Z" name="Failed suite [Selenium]" finished-at="2021-04-10T02:28:53Z" duration-ms="193">
    <groups>
    </groups>
    <test started-at="2021-04-10T02:28:53Z" name="Regression(failed)" finished-at="2021-04-10T02:28:53Z" duration-ms="193">
      <class name="com.edu.Testng.UserCreationMaster">
        <test-method signature="ModifyUser()[pri:2, instance:com.edu.Testng.UserCreationMaster@3af9c5b7]" started-at="2021-04-10T02:28:53Z" name="ModifyUser" finished-at="2021-04-10T02:28:53Z" duration-ms="75" status="FAIL">
          <exception class="java.lang.AssertionError">
            <message>
              <![CDATA[null]]>
            </message>
            <full-stacktrace>
              <![CDATA[java.lang.AssertionError: null
at org.testng.Assert.fail(Assert.java:96)
at org.testng.Assert.fail(Assert.java:103)
at com.edu.Testng.UserCreationMaster.ModifyUser(UserCreationMaster.java:23)
at java.base/jdk.internal.reflect.NativeMethodAccessorImpl.invoke0(Native Method)
at java.base/jdk.internal.reflect.NativeMethodAccessorImpl.invoke(Unknown Source)
at java.base/jdk.internal.reflect.DelegatingMethodAccessorImpl.invoke(Unknown Source)
at java.base/java.lang.reflect.Method.invoke(Unknown Source)
at org.testng.internal.MethodInvocationHelper.invokeMethod(MethodInvocationHelper.java:124)
at org.testng.internal.Invoker.invokeMethod(Invoker.java:583)
at org.testng.internal.Invoker.invokeTestMethod(Invoker.java:719)
at org.testng.internal.Invoker.invokeTestMethods(Invoker.java:989)
at org.testng.internal.TestMethodWorker.invokeTestMethods(TestMethodWorker.java:125)
at org.testng.internal.TestMethodWorker.run(TestMethodWorker.java:109)
at org.testng.TestRunner.privateRun(TestRunner.java:648)
at org.testng.TestRunner.run(TestRunner.java:505)
at org.testng.SuiteRunner.runTest(SuiteRunner.java:455)
at org.testng.SuiteRunner.runSequentially(SuiteRunner.java:450)
at org.testng.SuiteRunner.privateRun(SuiteRunner.java:415)
at org.testng.SuiteRunner.run(SuiteRunner.java:364)
at org.testng.SuiteRunnerWorker.runSuite(SuiteRunnerWorker.java:52)
at org.testng.SuiteRunnerWorker.run(SuiteRunnerWorker.java:84)
at org.testng.TestNG.runSuitesSequentially(TestNG.java:1208)
at org.testng.TestNG.runSuitesLocally(TestNG.java:1137)
at org.testng.TestNG.runSuites(TestNG.java:1049)
at org.testng.TestNG.run(TestNG.java:1017)
at org.testng.remote.AbstractRemoteTestNG.run(AbstractRemoteTestNG.java:114)
at org.testng.remote.RemoteTestNG.initAndRun(RemoteTestNG.java:251)
at org.testng.remote.RemoteTestNG.main(RemoteTestNG.java:77)
]]>
            </full-stacktrace>
          </exception> <!-- java.lang.AssertionError -->
          <reporter-output>
            <line>
              <![CDATA[User Modified Successfully]]>
            </line>
          </reporter-output>
        </test-method> <!-- ModifyUser -->
        <test-method signature="createUser()[pri:1, instance:com.edu.Testng.UserCreationMaster@3af9c5b7]" started-at="2021-04-10T02:28:53Z" name="createUser" finished-at="2021-04-10T02:28:53Z" depends-on-methods="com.edu.Testng.UserCreationMaster.ModifyUser" duration-ms="0" status="SKIP">
          <exception class="java.lang.Throwable">
            <message>
              <![CDATA[Method UserCreationMaster.createUser()[pri:1, instance:com.edu.Testng.UserCreationMaster@3af9c5b7] depends on not successfully finished methods]]>
            </message>
            <full-stacktrace>
              <![CDATA[java.lang.Throwable: Method UserCreationMaster.createUser()[pri:1, instance:com.edu.Testng.UserCreationMaster@3af9c5b7] depends on not successfully finished methods
at org.testng.internal.Invoker.invokeTestMethods(Invoker.java:888)
at org.testng.internal.TestMethodWorker.invokeTestMethods(TestMethodWorker.java:125)
at org.testng.internal.TestMethodWorker.run(TestMethodWorker.java:109)
at org.testng.TestRunner.privateRun(TestRunner.java:648)
at org.testng.TestRunner.run(TestRunner.java:505)
at org.testng.SuiteRunner.runTest(SuiteRunner.java:455)
at org.testng.SuiteRunner.runSequentially(SuiteRunner.java:450)
at org.testng.SuiteRunner.privateRun(SuiteRunner.java:415)
at org.testng.SuiteRunner.run(SuiteRunner.java:364)
at org.testng.SuiteRunnerWorker.runSuite(SuiteRunnerWorker.java:52)
at org.testng.SuiteRunnerWorker.run(SuiteRunnerWorker.java:84)
at org.testng.TestNG.runSuitesSequentially(TestNG.java:1208)
at org.testng.TestNG.runSuitesLocally(TestNG.java:1137)
at org.testng.TestNG.runSuites(TestNG.java:1049)
at org.testng.TestNG.run(TestNG.java:1017)
at org.testng.remote.AbstractRemoteTestNG.run(AbstractRemoteTestNG.java:114)
at org.testng.remote.RemoteTestNG.initAndRun(RemoteTestNG.java:251)
at org.testng.remote.RemoteTestNG.main(RemoteTestNG.java:77)
]]>
            </full-stacktrace>
          </exception> <!-- java.lang.Throwable -->
          <reporter-output>
          </reporter-output>
        </test-method> <!-- createUser -->
      </class> <!-- com.edu.Testng.UserCreationMaster -->
    </test> <!-- Regression(failed) -->
  </suite> <!-- Failed suite [Selenium] -->
</testng-results>
